Workbook
Name \_JUNK: #N/A
Name \0: #N/A
Name \a: #REF!
Name \B: #REF!
Name \C: #REF!
Name \D: #REF!
Name \e: #REF!
Name \g: #REF!
Name \h: #N/A
Name \I: #REF!
Name \j: #REF!
Name \l: #N/A
Name \m: #N/A
Name \p: #REF!
Name \r: #REF!
Name \s: #REF!
Name \t: #REF!
Name \z: #REF!
Name _.CDS_ID._: "SKOHL2"
Name _.CONTROL_ID._: 9
Name _.GIZMO_ID._: 6730
Name _.JOB_ID._: "J-700718611287015121329701210"
Name _.PAGE_ID._: 1
Name _.REPORT_DESCRIPTION._: "CMR Avg CMR Summary Report"
Name _.REPORT_ID._: 130
Name _.REPORT_NAME._: "CMR Avg CMR Summary Report [$W01_PARA_N5_value$]"
Name _.REPORT_SOURCE._: "EDB.3.0.1"
Name _.SERVER_HOST_ADDRESS._: "19.106.202.158"
Name _.SERVER_HOST_NAME._: "eccvas1777.md3.ford.com"
Name _.SITE_ID._: 700
Name _.TASK._: 2
Name _?: #N/A
Name _???: #N/A
Name _???????: #REF!
Name _?????????: #REF!
Name _??????????: #REF!
Name _???????????_01: #REF!
Name _??5???: #REF!
Name __?: #N/A
Name __???: #N/A
Name __???????: #REF!
Name __?????????: #REF!
Name __??????????: #REF!
Name __???????????_01: #REF!
Name __??5???: #REF!
Name ___: #REF!
Name _________________21: #REF!
Name ________________21: #REF!
Name _______________21: #REF!
Name ______________21: #REF!
Name _____________21: #REF!
Name ____________21: #REF!
Name ___________21: #REF!
Name __________21: #REF!
Name _________21: #REF!
Name ________21: #REF!
Name _______21: #REF!
Name _______A99999: #REF!
Name _______dkk1: #REF!
Name _______dkk2: #REF!

Sheet RMA Main BOM
K2: RMA BOM No | L2: RMA-BOM_25_180_R04 | M2: ver. 20260302 for Order#31
K3: Customer BOM No | L3: F0101023203 | M3: ver. JS-S4FL-V2-202510000 for Order#31
K4: Model | L4: V2-4SK | Z4: RMA BOM & COST | AG4: RMA Uplift COST (LCB port to RMA plant)
A5: =SUBTOTAL(3,Table13[Running]) -> 470 | K5: Series | L5: V2-S 4+0 Golf | AB5: 32.1892 | AG5: Currency : USD)
A6: Running | B6: Item | C6: Status | D6: Category | E6: Station | F6: Level | G6: Part Type | H6: UOM | I6: Customer P/N | J6: RMA P/N | K6: RMA Part Description | L6: Usage Qty | M6: Company | N6: Supplier | O6: Supplier Name | P6: Curren | Q6: Purchase Price | R6: Note | S6: Comment | U6: Category | V6: Trim | W6: Code | X6: Location | Y6: Country of Origin (COO) | Z6: Pure material/unit w/o Uplift | AA6: Currency | AB6: FX Conversion | AC6: Material cost (USD) | AD6: Material usage | AE6: Total material x usage (USD) | AG6: Uplift/unit | AH6: Material usage | AI6: Total Uplift
A7: 1 | D7: Chassis | F7: 1 | G7: Buy | H7: EACH | I7: F0102089001 | J7: =IF(LEFT(I7,2)="CO",I7,IF(LEFT(I7,2)="54","HT"&I7,IF(LEFT(I7,2)="KI","KT_"&MID(I7,5,24),IF(P7="THB","GT"&I7,IF(P7="USD","GU"&I7,IF(P7="CNY","GC"&I7)))))) -> GTF0102089001 | K7: Chassis Assy / DBL A-Arm Golf / V2-4S | L7: 1 | M7: RMA | N7: G0017 | O7: RMA Dynamics Co., Ltd. | P7: THB | U7: =TRIM(D7) -> Chassis | V7: =IF(U7="Seat-Option",LEFT(I7,18),TRIM(I7)) -> F0102089001 | W7: GT | X7: Local parts | Y7: Thailand | Z7: =_xlfn.XLOOKUP((W7&V7),[1]GRN_20260331!$H:$H,[1]GRN_20260331!$W:$W,0) -> 9699.8 | AA7: =IF(W7="GU","USD","THB") -> THB | AB7: =IF(AA7="THB",AB$5,1) -> 32.1892 | AC7: =Z7/AB7 -> 301.33709 | AD7: =L7 -> 1 | AE7: =AC7*AD7 -> 301.33709 | AG7: =_xlfn.XLOOKUP((W7&V7),[1]GRN_20260331!$H:$H,[1]GRN_20260331!$X:$X,0) -> 0 | AH7: =AD7 -> 1 | AI7: =AG7*AH7 -> 0
A8: =A7+1 -> 2 | D8: Other Steel | F8: 1 | G8: Buy | H8: EACH | I8: F0102089525M | J8: =IF(LEFT(I8,2)="CO",I8,IF(LEFT(I8,2)="54","HT"&I8,IF(LEFT(I8,2)="KI","KT_"&MID(I8,5,24),IF(P8="THB","GT"&I8,IF(P8="USD","GU"&I8,IF(P8="CNY","GC"&I8)))))) -> GTF0102089525M | K8: Battery Mt Brkt LH | L8: 1 | M8: RMA | N8: X0007 | O8: Xcellent Manufacturing (Thailand) Co.,Ltd. | P8: THB | U8: =TRIM(D8) -> Other Steel | V8: =IF(U8="Seat-Option",LEFT(I8,18),TRIM(I8)) -> F0102089525M | W8: GT | X8: Local parts | Y8: Thailand | Z8: =_xlfn.XLOOKUP((W8&V8),[1]GRN_20260331!$H:$H,[1]GRN_20260331!$W:$W,0) -> 137.92 | AA8: =IF(W8="GU","USD","THB") -> THB | AB8: =IF(AA8="THB",AB$5,1) -> 32.1892 | AC8: =Z8/AB8 -> 4.2846669 | AD8: =L8 -> 1 | AE8: =AC8*AD8 -> 4.2846669 | AG8: =_xlfn.XLOOKUP((W8&V8),[1]GRN_20260331!$H:$H,[1]GRN_20260331!$X:$X,0) -> 0 | AH8: =AD8 -> 1 | AI8: =AG8*AH8 -> 0
A9: =A8+1 -> 3 | D9: Other Steel | F9: 1 | G9: Buy | H9: EACH | I9: F0102089526M | J9: =IF(LEFT(I9,2)="CO",I9,IF(LEFT(I9,2)="54","HT"&I9,IF(LEFT(I9,2)="KI","KT_"&MID(I9,5,24),IF(P9="THB","GT"&I9,IF(P9="USD","GU"&I9,IF(P9="CNY","GC"&I9)))))) -> GTF0102089526M | K9: Battery Mt Brkt RH | L9: 1 | M9: RMA | N9: X0007 | O9: Xcellent Manufacturing (Thailand) Co.,Ltd. | P9: THB | U9: =TRIM(D9) -> Other Steel | V9: =IF(U9="Seat-Option",LEFT(I9,18),TRIM(I9)) -> F0102089526M | W9: GT | X9: Local parts | Y9: Thailand | Z9: =_xlfn.XLOOKUP((W9&V9),[1]GRN_20260331!$H:$H,[1]GRN_20260331!$W:$W,0) -> 159.71 | AA9: =IF(W9="GU","USD","THB") -> THB | AB9: =IF(AA9="THB",AB$5,1) -> 32.1892 | AC9: =Z9/AB9 -> 4.961602 | AD9: =L9 -> 1 | AE9: =AC9*AD9 -> 4.961602 | AG9: =_xlfn.XLOOKUP((W9&V9),[1]GRN_20260331!$H:$H,[1]GRN_20260331!$X:$X,0) -> 0 | AH9: =AD9 -> 1 | AI9: =AG9*AH9 -> 0
A10: =A9+1 -> 4 | D10: Other Steel | F10: 1 | G10: Buy | H10: EACH | I10: F0102063502M | J10: =IF(LEFT(I10,2)="CO",I10,IF(LEFT(I10,2)="54","HT"&I10,IF(LEFT(I10,2)="KI","KT_"&MID(I10,5,24),IF(P10="THB","GT"&I10,IF(P10="USD","GU"&I10,IF(P10="CNY","GC"&I10)))))) -> GTF0102063502M | K10: FRT Baffle Plate | L10: 1 | M10: RMA | N10: X0007 | O10: Xcellent Manufacturing (Thailand) Co.,Ltd. | P10: THB | U10: =TRIM(D10) -> Other Steel | V10: =IF(U10="Seat-Option",LEFT(I10,18),TRIM(I10)) -> F0102063502M | W10: GT | X10: Local parts | Y10: Thailand | Z10: =_xlfn.XLOOKUP((W10&V10),[1]GRN_20260331!$H:$H,[1]GRN_20260331!$W:$W,0) -> 311.7 | AA10: =IF(W10="GU","USD","THB") -> THB | AB10: =IF(AA10="THB",AB$5,1) -> 32.1892 | AC10: =Z10/AB10 -> 9.6833721 | AD10: =L10 -> 1 | AE10: =AC10*AD10 -> 9.6833721 | AG10: =_xlfn.XLOOKUP((W10&V10),[1]GRN_20260331!$H:$H,[1]GRN_20260331!$X:$X,0) -> 0 | AH10: =AD10 -> 1 | AI10: =AG10*AH10 -> 0
A11: =A10+1 -> 5 | D11: Other Steel | F11: 1 | G11: Buy | H11: EACH | I11: F0102089540M | J11: =IF(LEFT(I11,2)="CO",I11,IF(LEFT(I11,2)="54","HT"&I11,IF(LEFT(I11,2)="KI","KT_"&MID(I11,5,24),IF(P11="THB","GT"&I11,IF(P11="USD","GU"&I11,IF(P11="CNY","GC"&I11)))))) -> GTF0102089540M | K11: Lower Base Plate | L11: 1 | M11: RMA | N11: X0007 | O11: Xcellent Manufacturing (Thailand) Co.,Ltd. | P11: THB | U11: =TRIM(D11) -> Other Steel | V11: =IF(U11="Seat-Option",LEFT(I11,18),TRIM(I11)) -> F0102089540M | W11: GT | X11: Local parts | Y11: Thailand | Z11: =_xlfn.XLOOKUP((W11&V11),[1]GRN_20260331!$H:$H,[1]GRN_20260331!$W:$W,0) -> 862.32 | AA11: =IF(W11="GU","USD","THB") -> THB | AB11: =IF(AA11="THB",AB$5,1) -> 32.1892 | AC11: =Z11/AB11 -> 26.789109 | AD11: =L11 -> 1 | AE11: =AC11*AD11 -> 26.789109 | AG11: =_xlfn.XLOOKUP((W11&V11),[1]GRN_20260331!$H:$H,[1]GRN_20260331!$X:$X,0) -> 0 | AH11: =AD11 -> 1 | AI11: =AG11*AH11 -> 0
A12: =A11+1 -> 6 | D12: Powertrain | F12: 1 | G12: Buy | H12: EACH | I12: F0201013007 | J12: =IF(LEFT(I12,2)="CO",I12,IF(LEFT(I12,2)="54","HT"&I12,IF(LEFT(I12,2)="KI","KT_"&MID(I12,5,24),IF(P12="THB","GT"&I12,IF(P12="USD","GU"&I12,IF(P12="CNY","GC"&I12)))))) -> GUF0201013007 | K12: Upper Control Arm | L12: 2 | M12: RMA | N12: Y0030 | O12: Yangzhou Wev International Trade Co.,Ltd. | P12: USD | U12: =TRIM(D12) -> Powertrain | V12: =IF(U12="Seat-Option",LEFT(I12,18),TRIM(I12)) -> F0201013007 | W12: GU | X12: Oversea-WEV | Y12: China | Z12: =_xlfn.XLOOKUP((W12&V12),[1]GRN_20260331!$H:$H,[1]GRN_20260331!$W:$W,0) -> 17.63 | AA12: =IF(W12="GU","USD","THB") -> USD | AB12: =IF(AA12="THB",AB$5,1) -> 1 | AC12: =Z12/AB12 -> 17.63 | AD12: =L12 -> 2 | AE12: =AC12*AD12 -> 35.26 | AG12: =_xlfn.XLOOKUP((W12&V12),[1]GRN_20260331!$H:$H,[1]GRN_20260331!$X:$X,0) -> 0.11468781 | AH12: =AD12 -> 2 | AI12: =AG12*AH12 -> 0.22937563
A13: =A12+1 -> 7 | D13: Powertrain | F13: 1 | G13: Buy | H13: EACH | I13: F0201013008 | J13: =IF(LEFT(I13,2)="CO",I13,IF(LEFT(I13,2)="54","HT"&I13,IF(LEFT(I13,2)="KI","KT_"&MID(I13,5,24),IF(P13="THB","GT"&I13,IF(P13="USD","GU"&I13,IF(P13="CNY","GC"&I13)))))) -> GUF0201013008 | K13: Lower Control Arm LH | L13: 1 | M13: RMA | N13: Y0030 | O13: Yangzhou Wev International Trade Co.,Ltd. | P13: USD | U13: =TRIM(D13) -> Powertrain | V13: =IF(U13="Seat-Option",LEFT(I13,18),TRIM(I13)) -> F0201013008 | W13: GU | X13: Oversea-WEV | Y13: China | Z13: =_xlfn.XLOOKUP((W13&V13),[1]GRN_20260331!$H:$H,[1]GRN_20260331!$W:$W,0) -> 21.51 | AA13: =IF(W13="GU","USD","THB") -> USD | AB13: =IF(AA13="THB",AB$5,1) -> 1 | AC13: =Z13/AB13 -> 21.51 | AD13: =L13 -> 1 | AE13: =AC13*AD13 -> 21.51 | AG13: =_xlfn.XLOOKUP((W13&V13),[1]GRN_20260331!$H:$H,[1]GRN_20260331!$X:$X,0) -> 0.13992843 | AH13: =AD13 -> 1 | AI13: =AG13*AH13 -> 0.13992843
A14: =A13+1 -> 8 | D14: Powertrain | F14: 1 | G14: Buy | H14: EACH | I14: F0201013009 | J14: =IF(LEFT(I14,2)="CO",I14,IF(LEFT(I14,2)="54","HT"&I14,IF(LEFT(I14,2)="KI","KT_"&MID(I14,5,24),IF(P14="THB","GT"&I14,IF(P14="USD","GU"&I14,IF(P14="CNY","GC"&I14)))))) -> GUF0201013009 | K14: Lower Control Arm RH | L14: 1 | M14: RMA | N14: Y0030 | O14: Yangzhou Wev International Trade Co.,Ltd. | P14: USD | U14: =TRIM(D14) -> Powertrain | V14: =IF(U14="Seat-Option",LEFT(I14,18),TRIM(I14)) -> F0201013009 | W14: GU | X14: Oversea-WEV | Y14: China | Z14: =_xlfn.XLOOKUP((W14&V14),[1]GRN_20260331!$H:$H,[1]GRN_20260331!$W:$W,0) -> 21.51 | AA14: =IF(W14="GU","USD","THB") -> USD | AB14: =IF(AA14="THB",AB$5,1) -> 1 | AC14: =Z14/AB14 -> 21.51 | AD14: =L14 -> 1 | AE14: =AC14*AD14 -> 21.51 | AG14: =_xlfn.XLOOKUP((W14&V14),[1]GRN_20260331!$H:$H,[1]GRN_20260331!$X:$X,0) -> 0.13992843 | AH14: =AD14 -> 1 | AI14: =AG14*AH14 -> 0.13992843
A15: =A14+1 -> 9 | D15: Powertrain | F15: 1 | G15: Buy | H15: EACH | I15: F0201013010 | J15: =IF(LEFT(I15,2)="CO",I15,IF(LEFT(I15,2)="54","HT"&I15,IF(LEFT(I15,2)="KI","KT_"&MID(I15,5,24),IF(P15="THB","GT"&I15,IF(P15="USD","GU"&I15,IF(P15="CNY","GC"&I15)))))) -> GUF0201013010 | K15: Adjustable Ball Socket Assy | L15: 2 | M15: RMA | N15: Y0030 | O15: Yangzhou Wev International Trade Co.,Ltd. | P15: USD | U15: =TRIM(D15) -> Powertrain | V15: =IF(U15="Seat-Option",LEFT(I15,18),TRIM(I15)) -> F0201013010 | W15: GU | X15: Oversea-WEV | Y15: China | Z15: =_xlfn.XLOOKUP((W15&V15),[1]GRN_20260331!$H:$H,[1]GRN_20260331!$W:$W,0) -> 3.8 | AA15: =IF(W15="GU","USD","THB") -> USD | AB15: =IF(AA15="THB",AB$5,1) -> 1 | AC15: =Z15/AB15 -> 3.8 | AD15: =L15 -> 2 | AE15: =AC15*AD15 -> 7.6 | AG15: =_xlfn.XLOOKUP((W15&V15),[1]GRN_20260331!$H:$H,[1]GRN_20260331!$X:$X,0) -> 0.024719547 | AH15: =AD15 -> 2 | AI15: =AG15*AH15 -> 0.049439095
A16: =A15+1 -> 10 | C16: Remove - 20260302 | D16: Powertrain | F16: 1 | G16: Buy | H16: EACH | I16: F0202006036 | J16: =IF(LEFT(I16,2)="CO",I16,IF(LEFT(I16,2)="54","HT"&I16,IF(LEFT(I16,2)="KI","KT_"&MID(I16,5,24),IF(P16="THB","GT"&I16,IF(P16="USD","GU"&I16,IF(P16="CNY","GC"&I16)))))) -> GUF0202006036 | K16: FRT Shock Absorber Assy | L16: 2 | M16: RMA | N16: Y0030 | O16: Yangzhou Wev International Trade Co.,Ltd. | P16: USD | R16: WL-ECN_2026-026 | U16: =TRIM(D16) -> Powertrain | V16: =IF(U16="Seat-Option",LEFT(I16,18),TRIM(I16)) -> F0202006036 | W16: GU | X16: Oversea-WEV | AD16: =L16 -> 2 | AE16: =Z16*AD16 -> 0 | AH16: =AD16 -> 2 | AI16: =AG16*AH16 -> 0
A17: 11 | C17: Add - 20260302 | D17: Powertrain | F17: 1 | G17: Buy | H17: EACH | I17: F0202006096 | J17: =IF(LEFT(I17,2)="CO",I17,IF(LEFT(I17,2)="54","HT"&I17,IF(LEFT(I17,2)="KI","KT_"&MID(I17,5,24),IF(P17="THB","GT"&I17,IF(P17="USD","GU"&I17,IF(P17="CNY","GC"&I17)))))) -> GUF0202006096 | K17: FRT Shock Absorber Assy V2S | L17: 2 | M17: RMA | N17: Y0030 | O17: Yangzhou Wev International Trade Co.,Ltd. | P17: USD | R17: WL-ECN_2026-026 | U17: =TRIM(D17) -> Powertrain | V17: =IF(U17="Seat-Option",LEFT(I17,18),TRIM(I17)) -> F0202006096 | W17: GU | X17: Oversea-WEV | Y17: China | Z17: =_xlfn.XLOOKUP((W17&V17),[1]GRN_20260331!$H:$H,[1]GRN_20260331!$W:$W,0) -> 10.95 | AA17: =IF(W17="GU","USD","THB") -> USD | AB17: =IF(AA17="THB",AB$5,1) -> 1 | AC17: =Z17/AB17 -> 10.95 | AD17: =L17 -> 2 | AE17: =AC17*AD17 -> 21.9 | AG17: =_xlfn.XLOOKUP((W17&V17),[1]GRN_20260331!$H:$H,[1]GRN_20260331!$X:$X,0) -> 0.12680912 | AH17: =AD17 -> 2 | AI17: =AG17*AH17 -> 0.25361823
A18: 12 | D18: Powertrain | F18: 1 | G18: Buy | H18: EACH | I18: F0201002015 | J18: =IF(LEFT(I18,2)="CO",I18,IF(LEFT(I18,2)="54","HT"&I18,IF(LEFT(I18,2)="KI","KT_"&MID(I18,5,24),IF(P18="THB","GT"&I18,IF(P18="USD","GU"&I18,IF(P18="CNY","GC"&I18)))))) -> GUF0201002015 | K18: FRT Wheel Cyl Fixing Plate | L18: 2 | M18: RMA | N18: Y0030 | O18: Yangzhou Wev International Trade Co.,Ltd. | P18: USD | U18: =TRIM(D18) -> Powertrain | V18: =IF(U18="Seat-Option",LEFT(I18,18),TRIM(I18)) -> F0201002015 | W18: GU | X18: Oversea-WEV | Y18: China | Z18: =_xlfn.XLOOKUP((W18&V18),[1]GRN_20260331!$H:$H,[1]GRN_20260331!$W:$W,0) -> 1.94 | AA18: =IF(W18="GU","USD","THB") -> USD | AB18: =IF(AA18="THB",AB$5,1) -> 1 | AC18: =Z18/AB18 -> 1.94 | AD18: =L18 -> 2 | AE18: =AC18*AD18 -> 3.88 | AG18: =_xlfn.XLOOKUP((W18&V18),[1]GRN_20260331!$H:$H,[1]GRN_20260331!$X:$X,0) -> 0.013880599 | AH18: =AD18 -> 2 | AI18: =AG18*AH18 -> 0.027761198
A19: 13 | D19: Powertrain | F19: 1 | G19: Buy | H19: EACH | I19: F0201002034 | J19: =IF(LEFT(I19,2)="CO",I19,IF(LEFT(I19,2)="54","HT"&I19,IF(LEFT(I19,2)="KI","KT_"&MID(I19,5,24),IF(P19="THB","GT"&I19,IF(P19="USD","GU"&I19,IF(P19="CNY","GC"&I19)))))) -> GUF0201002034 | K19: FRT Brake Caliper LH BLK | L19: 1 | M19: RMA | N19: Y0030 | O19: Yangzhou Wev International Trade Co.,Ltd. | P19: USD | U19: =TRIM(D19) -> Powertrain | V19: =IF(U19="Seat-Option",LEFT(I19,18),TRIM(I19)) -> F0201002034 | W19: GU | X19: Oversea-WEV | Y19: China | Z19: =_xlfn.XLOOKUP((W19&V19),[1]GRN_20260331!$H:$H,[1]GRN_20260331!$W:$W,0) -> 13.89 | AA19: =IF(W19="GU","USD","THB") -> USD | AB19: =IF(AA19="THB",AB$5,1) -> 1 | AC19: =Z19/AB19 -> 13.89 | AD19: =L19 -> 1 | AE19: =AC19*AD19 -> 13.89 | AG19: =_xlfn.XLOOKUP((W19&V19),[1]GRN_20260331!$H:$H,[1]GRN_20260331!$X:$X,0) -> 0.11017704 | AH19: =AD19 -> 1 | AI19: =AG19*AH19 -> 0.11017704
A20: 14 | D20: Powertrain | F20: 1 | G20: Buy | H20: EACH | I20: F0201002035 | J20: =IF(LEFT(I20,2)="CO",I20,IF(LEFT(I20,2)="54","HT"&I20,IF(LEFT(I20,2)="KI","KT_"&MID(I20,5,24),IF(P20="THB","GT"&I20,IF(P20="USD","GU"&I20,IF(P20="CNY","GC"&I20)))))) -> GUF0201002035 | K20: FRT Brake Caliper RH BLK | L20: 1 | M20: RMA | N20: Y0030 | O20: Yangzhou Wev International Trade Co.,Ltd. | P20: USD | U20: =TRIM(D20) -> Powertrain | V20: =IF(U20="Seat-Option",LEFT(I20,18),TRIM(I20)) -> F0201002035 | W20: GU | X20: Oversea-WEV | Y20: China | Z20: =_xlfn.XLOOKUP((W20&V20),[1]GRN_20260331!$H:$H,[1]GRN_20260331!$W:$W,0) -> 13.89 | AA20: =IF(W20="GU","USD","THB") -> USD | AB20: =IF(AA20="THB",AB$5,1) -> 1 | AC20: =Z20/AB20 -> 13.89 | AD20: =L20 -> 1 | AE20: =AC20*AD20 -> 13.89 | AG20: =_xlfn.XLOOKUP((W20&V20),[1]GRN_20260331!$H:$H,[1]GRN_20260331!$X:$X,0) -> 0.11017704 | AH20: =AD20 -> 1 | AI20: =AG20*AH20 -> 0.11017704
A21: 15 | D21: Powertrain | F21: 1 | G21: Buy | H21: EACH | I21: F0201002018 | J21: =IF(LEFT(I21,2)="CO",I21,IF(LEFT(I21,2)="54","HT"&I21,IF(LEFT(I21,2)="KI","KT_"&MID(I21,5,24),IF(P21="THB","GT"&I21,IF(P21="USD","GU"&I21,IF(P21="CNY","GC"&I21)))))) -> GUF0201002018 | K21: Type-A Disc Brake Hub Assy | L21: 2 | M21: RMA | N21: Y0030 | O21: Yangzhou Wev International Trade Co.,Ltd. | P21: USD | U21: =TRIM(D21) -> Powertrain | V21: =IF(U21="Seat-Option",LEFT(I21,18),TRIM(I21)) -> F0201002018 | W21: GU | X21: Oversea-WEV | Y21: China | Z21: =_xlfn.XLOOKUP((W21&V21),[1]GRN_20260331!$H:$H,[1]GRN_20260331!$W:$W,0) -> 28.95 | AA21: =IF(W21="GU","USD","THB") -> USD | AB21: =IF(AA21="THB",AB$5,1) -> 1 | AC21: =Z21/AB21 -> 28.95 | AD21: =L21 -> 2 | AE21: =AC21*AD21 -> 57.9 | AG21: =_xlfn.XLOOKUP((W21&V21),[1]GRN_20260331!$H:$H,[1]GRN_20260331!$X:$X,0) -> 0.20711778 | AH21: =AD21 -> 2 | AI21: =AG21*AH21 -> 0.41423555
A22: 16 | D22: Powertrain | F22: 1 | G22: Buy | H22: EACH | I22: F0201011011 | J22: =IF(LEFT(I22,2)="CO",I22,IF(LEFT(I22,2)="54","HT"&I22,IF(LEFT(I22,2)="KI","KT_"&MID(I22,5,24),IF(P22="THB","GT"&I22,IF(P22="USD","GU"&I22,IF(P22="CNY","GC"&I22)))))) -> GUF0201011011 | K22: Steering Knuckle LH | L22: 1 | M22: RMA | N22: Y0030 | O22: Yangzhou Wev International Trade Co.,Ltd. | P22: USD | U22: =TRIM(D22) -> Powertrain | V22: =IF(U22="Seat-Option",LEFT(I22,18),TRIM(I22)) -> F0201011011 | W22: GU | X22: Oversea-WEV | Y22: China | Z22: =_xlfn.XLOOKUP((W22&V22),[1]GRN_20260331!$H:$H,[1]GRN_20260331!$W:$W,0) -> 21.83 | AA22: =IF(W22="GU","USD","THB") -> USD | AB22: =IF(AA22="THB",AB$5,1) -> 1 | AC22: =Z22/AB22 -> 21.83 | AD22: =L22 -> 1 | AE22: =AC22*AD22 -> 21.83 | AG22: =_xlfn.XLOOKUP((W22&V22),[1]GRN_20260331!$H:$H,[1]GRN_20260331!$X:$X,0) -> 0.15617972 | AH22: =AD22 -> 1 | AI22: =AG22*AH22 -> 0.15617972
A23: 17 | D23: Powertrain | F23: 1 | G23: Buy | H23: EACH | I23: F0201011012 | J23: =IF(LEFT(I23,2)="CO",I23,IF(LEFT(I23,2)="54","HT"&I23,IF(LEFT(I23,2)="KI","KT_"&MID(I23,5,24),IF(P23="THB","GT"&I23,IF(P23="USD","GU"&I23,IF(P23="CNY","GC"&I23)))))) -> GUF0201011012 | K23: Steering Knuckle RH | L23: 1 | M23: RMA | N23: Y0030 | O23: Yangzhou Wev International Trade Co.,Ltd. | P23: USD | U23: =TRIM(D23) -> Powertrain | V23: =IF(U23="Seat-Option",LEFT(I23,18),TRIM(I23)) -> F0201011012 | W23: GU | X23: Oversea-WEV | Y23: China | Z23: =_xlfn.XLOOKUP((W23&V23),[1]GRN_20260331!$H:$H,[1]GRN_20260331!$W:$W,0) -> 21.83 | AA23: =IF(W23="GU","USD","THB") -> USD | AB23: =IF(AA23="THB",AB$5,1) -> 1 | AC23: =Z23/AB23 -> 21.83 | AD23: =L23 -> 1 | AE23: =AC23*AD23 -> 21.83 | AG23: =_xlfn.XLOOKUP((W23&V23),[1]GRN_20260331!$H:$H,[1]GRN_20260331!$X:$X,0) -> 0.15617972 | AH23: =AD23 -> 1 | AI23: =AG23*AH23 -> 0.15617972
A24: 18 | D24: Powertrain | F24: 1 | G24: Buy | H24: EACH | I24: F0202006086 | J24: =IF(LEFT(I24,2)="CO",I24,IF(LEFT(I24,2)="54","HT"&I24,IF(LEFT(I24,2)="KI","KT_"&MID(I24,5,24),IF(P24="THB","GT"&I24,IF(P24="USD","GU"&I24,IF(P24="CNY","GC"&I24)))))) -> GUF0202006086 | K24: RR Shock Absorber (Golf) | L24: 2 | M24: RMA | N24: Y0030 | O24: Yangzhou Wev International Trade Co.,Ltd. | P24: USD | U24: =TRIM(D24) -> Powertrain | V24: =IF(U24="Seat-Option",LEFT(I24,18),TRIM(I24)) -> F0202006086 | W24: GU | X24: Oversea-WEV | Y24: China | Z24: =_xlfn.XLOOKUP((W24&V24),[1]GRN_20260331!$H:$H,[1]GRN_20260331!$W:$W,0) -> 12.45 | AA24: =IF(W24="GU","USD","THB") -> USD | AB24: =IF(AA24="THB",AB$5,1) -> 1 | AC24: =Z24/AB24 -> 12.45 | AD24: =L24 -> 2 | AE24: =AC24*AD24 -> 24.9 | AG24: =_xlfn.XLOOKUP((W24&V24),[1]GRN_20260331!$H:$H,[1]GRN_20260331!$X:$X,0) -> 0.080991984 | AH24: =AD24 -> 2 | AI24: =AG24*AH24 -> 0.16198397
A25: 19 | D25: Powertrain | F25: 1 | G25: Buy | H25: SET | I25: F0201003112 | J25: =IF(LEFT(I25,2)="CO",I25,IF(LEFT(I25,2)="54","HT"&I25,IF(LEFT(I25,2)="KI","KT_"&MID(I25,5,24),IF(P25="THB","GT"&I25,IF(P25="USD","GU"&I25,IF(P25="CNY","GC"&I25)))))) -> GUF0201003112 | K25: RR Axle / Electromag Park / Disc (Golf) | L25: 1 | M25: RMA | N25: Y0030 | O25: Yangzhou Wev International Trade Co.,Ltd. | P25: USD | U25: =TRIM(D25) -> Powertrain | V25: =IF(U25="Seat-Option",LEFT(I25,18),TRIM(I25)) -> F0201003112 | W25: GU | X25: Oversea-WEV | Y25: China | Z25: =_xlfn.XLOOKUP((W25&V25),[1]GRN_20260331!$H:$H,[1]GRN_20260331!$W:$W,0) -> 217.52 | AA25: =IF(W25="GU","USD","THB") -> USD | AB25: =IF(AA25="THB",AB$5,1) -> 1 | AC25: =Z25/AB25 -> 217.52 | AD25: =L25 -> 1 | AE25: =AC25*AD25 -> 217.52 | AG25: =_xlfn.XLOOKUP((W25&V25),[1]GRN_20260331!$H:$H,[1]GRN_20260331!$X:$X,0) -> 1.73598 | AH25: =AD25 -> 1 | AI25: =AG25*AH25 -> 1.73598
A26: 20 | D26: Powertrain | F26: 1 | G26: Buy | H26: EACH | I26: F0201004009 | J26: =IF(LEFT(I26,2)="CO",I26,IF(LEFT(I26,2)="54","HT"&I26,IF(LEFT(I26,2)="KI","KT_"&MID(I26,5,24),IF(P26="THB","GT"&I26,IF(P26="USD","GU"&I26,IF(P26="CNY","GC"&I26)))))) -> GUF0201004009 | K26: Electromag Brake | L26: 1 | M26: RMA | N26: Y0030 | O26: Yangzhou Wev International Trade Co.,Ltd. | P26: USD | U26: =TRIM(D26) -> Powertrain | V26: =IF(U26="Seat-Option",LEFT(I26,18),TRIM(I26)) -> F0201004009 | W26: GU | X26: Oversea-WEV | Y26: China | Z26: =_xlfn.XLOOKUP((W26&V26),[1]GRN_20260331!$H:$H,[1]GRN_20260331!$W:$W,0) -> 40.11 | AA26: =IF(W26="GU","USD","THB") -> USD | AB26: =IF(AA26="THB",AB$5,1) -> 1 | AC26: =Z26/AB26 -> 40.11 | AD26: =L26 -> 1 | AE26: =AC26*AD26 -> 40.11 | AG26: =_xlfn.XLOOKUP((W26&V26),[1]GRN_20260331!$H:$H,[1]GRN_20260331!$X:$X,0) -> 0.29134032 | AH26: =AD26 -> 1 | AI26: =AG26*AH26 -> 0.29134032
A27: 21 | D27: Powertrain | F27: 1 | G27: Buy | H27: EACH | I27: F0201013021 | J27: =IF(LEFT(I27,2)="CO",I27,IF(LEFT(I27,2)="54","HT"&I27,IF(LEFT(I27,2)="KI","KT_"&MID(I27,5,24),IF(P27="THB","GT"&I27,IF(P27="USD","GU"&I27,IF(P27="CNY","GC"&I27)))))) -> GUF0201013021 | K27: RR Trailing Arm (Heavy-Duty) | L27: 2 | M27: RMA | N27: Y0030 | O27: Yangzhou Wev International Trade Co.,Ltd. | P27: USD | U27: =TRIM(D27) -> Powertrain | V27: =IF(U27="Seat-Option",LEFT(I27,18),TRIM(I27)) -> F0201013021 | W27: GU | X27: Oversea-WEV | Y27: China | Z27: =_xlfn.XLOOKUP((W27&V27),[1]GRN_20260331!$H:$H,[1]GRN_20260331!$W:$W,0) -> 10.03 | AA27: =IF(W27="GU","USD","THB") -> USD | AB27: =IF(AA27="THB",AB$5,1) -> 1 | AC27: =Z27/AB27 -> 10.03 | AD27: =L27 -> 2 | AE27: =AC27*AD27 -> 20.06 | AG27: =_xlfn.XLOOKUP((W27&V27),[1]GRN_20260331!$H:$H,[1]GRN_20260331!$X:$X,0) -> 0.072851063 | AH27: =AD27 -> 2 | AI27: =AG27*AH27 -> 0.14570213
A28: 22 | D28: Powertrain | F28: 1 | G28: Buy | H28: EACH | I28: F0201009030 | J28: =IF(LEFT(I28,2)="CO",I28,IF(LEFT(I28,2)="54","HT"&I28,IF(LEFT(I28,2)="KI","KT_"&MID(I28,5,24),IF(P28="THB","GT"&I28,IF(P28="USD","GU"&I28,IF(P28="CNY","GC"&I28)))))) -> GUF0201009030 | K28: RR Stabilizer Bar | L28: 1 | M28: RMA | N28: Y0030 | O28: Yangzhou Wev International Trade Co.,Ltd. | P28: USD | U28: =TRIM(D28) -> Powertrain | V28: =IF(U28="Seat-Option",LEFT(I28,18),TRIM(I28)) -> F0201009030 | W28: GU | X28: Oversea-WEV | Y28: China | Z28: =_xlfn.XLOOKUP((W28&V28),[1]GRN_20260331!$H:$H,[1]GRN_20260331!$W:$W,0) -> 5.34 | AA28: =IF(W28="GU","USD","THB") -> USD | AB28: =IF(AA28="THB",AB$5,1) -> 1 | AC28: =Z28/AB28 -> 5.34 | AD28: =L28 -> 1 | AE28: =AC28*AD28 -> 5.34 | AG28: =_xlfn.XLOOKUP((W28&V28),[1]GRN_20260331!$H:$H,[1]GRN_20260331!$X:$X,0) -> 0.038786929 | AH28: =AD28 -> 1 | AI28: =AG28*AH28 -> 0.038786929
A29: 23 | D29: Powertrain | F29: 1 | G29: Make | H29: SET | I29: KIT_WHEEL_S4FNV2_00-00 | J29: =IF(LEFT(I29,2)="CO",I29,IF(LEFT(I29,2)="54","HT"&I29,IF(LEFT(I29,2)="KI","KT_"&MID(I29,5,24),IF(P29="THB","GT"&I29,IF(P29="USD","GU"&I29,IF(P29="CNY","GC"&I29)))))) -> KT_WHEEL_S4FNV2_00-00 | K29: Wheel&Tire Assy V2S 4+0 Golf | L29: 4 | M29: RMA | N29: P0001 | O29: Main Parts Supplier Template | P29: THB | U29: =TRIM(D29) -> Powertrain | V29: =IF(U29="Seat-Option",LEFT(I29,18),TRIM(I29)) -> KIT_WHEEL_S4FNV2_00-00 | W29: GT | X29: Local parts | Z29: 0 | AA29: =IF(W29="GU","USD","THB") -> THB | AB29: =IF(AA29="THB",AB$5,1) -> 32.1892 | AC29: =Z29/AB29 -> 0 | AD29: =L29 -> 4 | AE29: =Z29*AD29 -> 0 | AG29: 0 | AH29: =AD29 -> 4 | AI29: =AG29*AH29 -> 0
A30: 24 | D30: Powertrain | F30: 2 | G30: Buy | H30: EACH | I30: P-WHEELS4FNV2_00-00 | J30: =IF(LEFT(I30,2)="CO",I30,IF(LEFT(I30,2)="54","HT"&I30,IF(LEFT(I30,2)="KI","KT_"&MID(I30,5,24),IF(P30="THB","GT"&I30,IF(P30="USD","GU"&I30,IF(P30="CNY","GC"&I30)))))) -> GTP-WHEELS4FNV2_00-00 | K30: Process Wheel&Tire Assy V2S 4+0 Golf | L30: 1 | M30: RMA | N30: F0129 | O30: Feiyu Rubber Recycle (Thailand) Co., Ltd. | P30: THB | U30: =TRIM(D30) -> Powertrain | V30: =IF(U30="Seat-Option",LEFT(I30,18),TRIM(I30)) -> P-WHEELS4FNV2_00-00 | W30: GT | X30: Local parts | Y30: Thailand | Z30: =_xlfn.XLOOKUP((W30&V30),[1]GRN_20260331!$H:$H,[1]GRN_20260331!$W:$W,0) -> 42 | AA30: =IF(W30="GU","USD","THB") -> THB | AB30: =IF(AA30="THB",AB$5,1) -> 32.1892 | AC30: =Z30/AB30 -> 1.3047855 | AD30: 4 | AE30: =AC30*AD30 -> 5.2191418 | AG30: =_xlfn.XLOOKUP((W30&V30),[1]GRN_20260331!$H:$H,[1]GRN_20260331!$X:$X,0) -> 0 | AH30: =AD30 -> 4 | AI30: =AG30*AH30 -> 0
A31: 25 | D31: Powertrain | F31: 2 | G31: Buy | H31: EACH | I31: F0202009204 | J31: =IF(LEFT(I31,2)="CO",I31,IF(LEFT(I31,2)="54","HT"&I31,IF(LEFT(I31,2)="KI","KT_"&MID(I31,5,24),IF(P31="THB","GT"&I31,IF(P31="USD","GU"&I31,IF(P31="CNY","GC"&I31)))))) -> GTF0202009204 | K31: TIRE 215/35R14 AR20 | L31: 1 | M31: RMA | N31: F0129 | O31: Feiyu Rubber Recycle (Thailand) Co., Ltd. | P31: THB | U31: =TRIM(D31) -> Powertrain | V31: =IF(U31="Seat-Option",LEFT(I31,18),TRIM(I31)) -> F0202009204 | W31: GT | X31: Local parts | Y31: Thailand | Z31: =_xlfn.XLOOKUP((W31&V31),[1]GRN_20260331!$H:$H,[1]GRN_20260331!$W:$W,0) -> 1011.2 | AA31: =IF(W31="GU","USD","THB") -> THB | AB31: =IF(AA31="THB",AB$5,1) -> 32.1892 | AC31: =Z31/AB31 -> 31.414263 | AD31: 4 | AE31: =AC31*AD31 -> 125.65705 | AG31: =_xlfn.XLOOKUP((W31&V31),[1]GRN_20260331!$H:$H,[1]GRN_20260331!$X:$X,0) -> 0 | AH31: =AD31 -> 4 | AI31: =AG31*AH31 -> 0
A32: 26 | D32: Powertrain | F32: 2 | G32: Buy | H32: EACH | I32: F0202010215.1 | J32: =IF(LEFT(I32,2)="CO",I32,IF(LEFT(I32,2)="54","HT"&I32,IF(LEFT(I32,2)="KI","KT_"&MID(I32,5,24),IF(P32="THB","GT"&I32,IF(P32="USD","GU"&I32,IF(P32="CNY","GC"&I32)))))) -> GTF0202010215.1 | K32: ALLOY WHEEL 14x7 ET-25 (E-02) w/o Logo | L32: 1 | M32: RMA | N32: V0059 | O32: Vossen Manufacture (Thailand) Co., Ltd. | P32: THB | U32: =TRIM(D32) -> Powertrain | V32: =IF(U32="Seat-Option",LEFT(I32,18),TRIM(I32)) -> F0202010215.1 | W32: GT | X32: Local parts | Y32: Thailand | Z32: =_xlfn.XLOOKUP((W32&V32),[1]GRN_20260331!$H:$H,[1]GRN_20260331!$W:$W,0) -> 1216.87 | AA32: =IF(W32="GU","USD","THB") -> THB | AB32: =IF(AA32="THB",AB$5,1) -> 32.1892 | AC32: =Z32/AB32 -> 37.803673 | AD32: 4 | AE32: =AC32*AD32 -> 151.21469 | AG32: =_xlfn.XLOOKUP((W32&V32),[1]GRN_20260331!$H:$H,[1]GRN_20260331!$X:$X,0) -> 0 | AH32: =AD32 -> 4 | AI32: =AG32*AH32 -> 0
A33: 27 | D33: Powertrain | F33: 2 | G33: Buy | H33: EACH | I33: F0202010215.2 | J33: =IF(LEFT(I33,2)="CO",I33,IF(LEFT(I33,2)="54","HT"&I33,IF(LEFT(I33,2)="KI","KT_"&MID(I33,5,24),IF(P33="THB","GT"&I33,IF(P33="USD","GU"&I33,IF(P33="CNY","GC"&I33)))))) -> GTF0202010215.2 | K33: WHEEL CAP (WHL-CAP-2 JF006) w/ S-Logo | L33: 1 | M33: RMA | N33: V0059 | O33: Vossen Manufacture (Thailand) Co., Ltd. | P33: THB | U33: =TRIM(D33) -> Powertrain | V33: =IF(U33="Seat-Option",LEFT(I33,18),TRIM(I33)) -> F0202010215.2 | W33: GT | X33: Local parts | Y33: Thailand | Z33: =_xlfn.XLOOKUP((W33&V33),[1]GRN_20260331!$H:$H,[1]GRN_20260331!$W:$W,0) -> 47.9 | AA33: =IF(W33="GU","USD","THB") -> THB | AB33: =IF(AA33="THB",AB$5,1) -> 32.1892 | AC33: =Z33/AB33 -> 1.4880767 | AD33: 4 | AE33: =AC33*AD33 -> 5.952307 | AG33: =_xlfn.XLOOKUP((W33&V33),[1]GRN_20260331!$H:$H,[1]GRN_20260331!$X:$X,0) -> 0 | AH33: =AD33 -> 4 | AI33: =AG33*AH33 -> 0
A34: 28 | D34: Powertrain | F34: 2 | G34: Buy | H34: EACH | I34: AIR-VALVE-TR413 | J34: =IF(LEFT(I34,2)="CO",I34,IF(LEFT(I34,2)="54","HT"&I34,IF(LEFT(I34,2)="KI","KT_"&MID(I34,5,24),IF(P34="THB","GT"&I34,IF(P34="USD","GU"&I34,IF(P34="CNY","GC"&I34)))))) -> GTAIR-VALVE-TR413 | K34: Air Valve TR413 | L34: 1 | M34: RMA | N34: V0059 | O34: Vossen Manufacture (Thailand) Co., Ltd. | P34: THB | U34: =TRIM(D34) -> Powertrain | V34: =IF(U34="Seat-Option",LEFT(I34,18),TRIM(I34)) -> AIR-VALVE-TR413 | W34: GT | X34: Local parts | Y34: Thailand | Z34: =_xlfn.XLOOKUP((W34&V34),[1]GRN_20260331!$H:$H,[1]GRN_20260331!$W:$W,0) -> 5.05 | AA34: =IF(W34="GU","USD","THB") -> THB | AB34: =IF(AA34="THB",AB$5,1) -> 32.1892 | AC34: =Z34/AB34 -> 0.15688492 | AD34: 4 | AE34: =AC34*AD34 -> 0.62753967 | AG34: =_xlfn.XLOOKUP((W34&V34),[1]GRN_20260331!$H:$H,[1]GRN_20260331!$X:$X,0) -> 0 | AH34: =AD34 -> 4 | AI34: =AG34*AH34 -> 0
A35: 29 | D35: Powertrain | F35: 1 | G35: Buy | H35: EACH | I35: F0204002044 | J35: =IF(LEFT(I35,2)="CO",I35,IF(LEFT(I35,2)="54","HT"&I35,IF(LEFT(I35,2)="KI","KT_"&MID(I35,5,24),IF(P35="THB","GT"&I35,IF(P35="USD","GU"&I35,IF(P35="CNY","GC"&I35)))))) -> GUF0204002044 | K35: Adjustable Steering Shaft Tube | L35: 1 | M35: RMA | N35: Y0030 | O35: Yangzhou Wev International Trade Co.,Ltd. | P35: USD | U35: =TRIM(D35) -> Powertrain | V35: =IF(U35="Seat-Option",LEFT(I35,18),TRIM(I35)) -> F0204002044 | W35: GU | X35: Oversea-WEV | Y35: China | Z35: =_xlfn.XLOOKUP((W35&V35),[1]GRN_20260331!$H:$H,[1]GRN_20260331!$W:$W,0) -> 15.06 | AA35: =IF(W35="GU","USD","THB") -> USD | AB35: =IF(AA35="THB",AB$5,1) -> 1 | AC35: =Z35/AB35 -> 15.06 | AD35: =L35 -> 1 | AE35: =AC35*AD35 -> 15.06 | AG35: =_xlfn.XLOOKUP((W35&V35),[1]GRN_20260331!$H:$H,[1]GRN_20260331!$X:$X,0) -> 0.8147093 | AH35: =AD35 -> 1 | AI35: =AG35*AH35 -> 0.8147093
A36: 30 | D36: Powertrain | F36: 1 | G36: Buy | H36: EACH | I36: F2101105015 | J36: =IF(LEFT(I36,2)="CO",I36,IF(LEFT(I36,2)="54","HT"&I36,IF(LEFT(I36,2)="KI","KT_"&MID(I36,5,24),IF(P36="THB","GT"&I36,IF(P36="USD","GU"&I36,IF(P36="CNY","GC"&I36)))))) -> GUF2101105015 | K36: Steering Shaft Tube Pin Shaft | L36: 2 | M36: RMA | N36: Y0030 | O36: Yangzhou Wev International Trade Co.,Ltd. | P36: USD | U36: =TRIM(D36) -> Powertrain | V36: =IF(U36="Seat-Option",LEFT(I36,18),TRIM(I36)) -> F2101105015 | W36: GU | X36: Oversea-WEV | Y36: China | Z36: =_xlfn.XLOOKUP((W36&V36),[1]GRN_20260331!$H:$H,[1]GRN_20260331!$W:$W,0) -> 0.61 | AA36: =IF(W36="GU","USD","THB") -> USD | AB36: =IF(AA36="THB",AB$5,1) -> 1 | AC36: =Z36/AB36 -> 0.61 | AD36: =L36 -> 2 | AE36: =AC36*AD36 -> 1.22 | AG36: =_xlfn.XLOOKUP((W36&V36),[1]GRN_20260331!$H:$H,[1]GRN_20260331!$X:$X,0) -> 0.004364423 | AH36: =AD36 -> 2 | AI36: =AG36*AH36 -> 0.008728846
A37: 31 | D37: Powertrain | F37: 1 | G37: Buy | H37: EACH | I37: F2101083021 | J37: =IF(LEFT(I37,2)="CO",I37,IF(LEFT(I37,2)="54","HT"&I37,IF(LEFT(I37,2)="KI","KT_"&MID(I37,5,24),IF(P37="THB","GT"&I37,IF(P37="USD","GU"&I37,IF(P37="CNY","GC"&I37)))))) -> GUF2101083021 | K37: Butterfly Spring d12.2 D25 t1.5 Ho2.05 | L37: 2 | M37: RMA | N37: Y0030 | O37: Yangzhou Wev International Trade Co.,Ltd. | P37: USD | U37: =TRIM(D37) -> Powertrain | V37: =IF(U37="Seat-Option",LEFT(I37,18),TRIM(I37)) -> F2101083021 | W37: GU | X37: Oversea-WEV | Y37: China | Z37: =_xlfn.XLOOKUP((W37&V37),[1]GRN_20260331!$H:$H,[1]GRN_20260331!$W:$W,0) -> 0.09 | AA37: =IF(W37="GU","USD","THB") -> USD | AB37: =IF(AA37="THB",AB$5,1) -> 1 | AC37: =Z37/AB37 -> 0.09 | AD37: =L37 -> 2 | AE37: =AC37*AD37 -> 0.18 | AG37: =_xlfn.XLOOKUP((W37&V37),[1]GRN_20260331!$H:$H,[1]GRN_20260331!$X:$X,0) -> 0.00064399563 | AH37: =AD37 -> 2 | AI37: =AG37*AH37 -> 0.0012879913
A38: 32 | D38: Powertrain | F38: 1 | G38: Buy | H38: EACH | I38: F0204002038 | J38: =IF(LEFT(I38,2)="CO",I38,IF(LEFT(I38,2)="54","HT"&I38,IF(LEFT(I38,2)="KI","KT_"&MID(I38,5,24),IF(P38="THB","GT"&I38,IF(P38="USD","GU"&I38,IF(P38="CNY","GC"&I38)))))) -> GUF0204002038 | K38: Steering Shaft Tube Gas Spring | L38: 1 | M38: RMA | N38: Y0030 | O38: Yangzhou Wev International Trade Co.,Ltd. | P38: USD | U38: =TRIM(D38) -> Powertrain | V38: =IF(U38="Seat-Option",LEFT(I38,18),TRIM(I38)) -> F0204002038 | W38: GU | X38: Oversea-WEV | Y38: China | Z38: =_xlfn.XLOOKUP((W38&V38),[1]GRN_20260331!$H:$H,[1]GRN_20260331!$W:$W,0) -> 7.84 | AA38: =IF(W38="GU","USD","THB") -> USD | AB38: =IF(AA38="THB",AB$5,1) -> 1 | AC38: =Z38/AB38 -> 7.84 | AD38: =L38 -> 1 | AE38: =AC38*AD38 -> 7.84 | AG38: =_xlfn.XLOOKUP((W38&V38),[1]GRN_20260331!$H:$H,[1]GRN_20260331!$X:$X,0) -> 0.051000857 | AH38: =AD38 -> 1 | AI38: =AG38*AH38 -> 0.051000857
A39: 33 | D39: Powertrain | F39: 1 | G39: Buy | H39: EACH | I39: F2101105014 | J39: =IF(LEFT(I39,2)="CO",I39,IF(LEFT(I39,2)="54","HT"&I39,IF(LEFT(I39,2)="KI","KT_"&MID(I39,5,24),IF(P39="THB","GT"&I39,IF(P39="USD","GU"&I39,IF(P39="CNY","GC"&I39)))))) -> GUF2101105014 | K39: Shaft Pin 8×30 Tri-chrome | L39: 2 | M39: RMA | N39: Y0030 | O39: Yangzhou Wev International Trade Co.,Ltd. | P39: USD | U39: =TRIM(D39) -> Powertrain | V39: =IF(U39="Seat-Option",LEFT(I39,18),TRIM(I39)) -> F2101105014 | W39: GU | X39: Oversea-WEV | Y39: China | Z39: =_xlfn.XLOOKUP((W39&V39),[1]GRN_20260331!$H:$H,[1]GRN_20260331!$W:$W,0) -> 0.05 | AA39: =IF(W39="GU","USD","THB") -> USD | AB39: =IF(AA39="THB",AB$5,1) -> 1 | AC39: =Z39/AB39 -> 0.05 | AD39: =L39 -> 2 | AE39: =AC39*AD39 -> 0.1 | AG39: =_xlfn.XLOOKUP((W39&V39),[1]GRN_20260331!$H:$H,[1]GRN_20260331!$X:$X,0) -> 0.00032539048 | AH39: =AD39 -> 2 | AI39: =AG39*AH39 -> 0.00065078095
A40: 34 | D40: Powertrain | F40: 1 | G40: Buy | H40: EACH | I40: F0204002032 | J40: =IF(LEFT(I40,2)="CO",I40,IF(LEFT(I40,2)="54","HT"&I40,IF(LEFT(I40,2)="KI","KT_"&MID(I40,5,24),IF(P40="THB","GT"&I40,IF(P40="USD","GU"&I40,IF(P40="CNY","GC"&I40)))))) -> GUF0204002032 | K40: Steering Shaft Tube Hoop 1 (WH2027K) | L40: 1 | M40: RMA | N40: Y0030 | O40: Yangzhou Wev International Trade Co.,Ltd. | P40: USD | U40: =TRIM(D40) -> Powertrain | V40: =IF(U40="Seat-Option",LEFT(I40,18),TRIM(I40)) -> F0204002032 | W40: GU | X40: Oversea-WEV | Y40: China | Z40: =_xlfn.XLOOKUP((W40&V40),[1]GRN_20260331!$H:$H,[1]GRN_20260331!$W:$W,0) -> 0.88 | AA40: =IF(W40="GU","USD","THB") -> USD | AB40: =IF(AA40="THB",AB$5,1) -> 1 | AC40: =Z40/AB40 -> 0.88 | AD40: =L40 -> 1 | AE40: =AC40*AD40 -> 0.88 | AG40: =_xlfn.XLOOKUP((W40&V40),[1]GRN_20260331!$H:$H,[1]GRN_20260331!$X:$X,0) -> 0.006295905 | AH40: =AD40 -> 1 | AI40: =AG40*AH40 -> 0.006295905
A41: 35 | D41: Powertrain | F41: 1 | G41: Buy | H41: EACH | I41: F0204001030 | J41: =IF(LEFT(I41,2)="CO",I41,IF(LEFT(I41,2)="54","HT"&I41,IF(LEFT(I41,2)="KI","KT_"&MID(I41,5,24),IF(P41="THB","GT"&I41,IF(P41="USD","GU"&I41,IF(P41="CNY","GC"&I41)))))) -> GUF0204001030 | K41: Multifunction Steering Wheel (SIVO) | L41: 1 | M41: RMA | N41: Y0030 | O41: Yangzhou Wev International Trade Co.,Ltd. | P41: USD | R41: Replaced F0204001015, WL-ECN_2025-060 | U41: =TRIM(D41) -> Powertrain | V41: =IF(U41="Seat-Option",LEFT(I41,18),TRIM(I41)) -> F0204001030 | W41: GU | X41: Oversea-WEV | Y41: China | Z41: =_xlfn.XLOOKUP((W41&V41),[1]GRN_20260331!$H:$H,[1]GRN_20260331!$W:$W,0) -> 56.6 | AA41: =IF(W41="GU","USD","THB") -> USD | AB41: =IF(AA41="THB",AB$5,1) -> 1 | AC41: =Z41/AB41 -> 56.6 | AD41: =L41 -> 1 | AE41: =AC41*AD41 -> 56.6 | AG41: =_xlfn.XLOOKUP((W41&V41),[1]GRN_20260331!$H:$H,[1]GRN_20260331!$X:$X,0) -> 0.71880197 | AH41: =AD41 -> 1 | AI41: =AG41*AH41 -> 0.71880197
...

Sheet GAT Main BOM
K2: RMA BOM No | L2: ='RMA Main BOM'!L2 -> RMA-BOM_25_180_R04 | M2: ='RMA Main BOM'!M2 -> ver. 20260302 for Order#31
K3: Customer BOM No | L3: ='RMA Main BOM'!L3 -> F0101023203 | M3: ='RMA Main BOM'!M3 -> ver. JS-S4FL-V2-202510000 for Order#31
K4: Model | L4: ='RMA Main BOM'!L4 -> V2-4SK | Z4: RMA BOM & COST | AG4: RMA Uplift COST (LCB port to RMA plant)
A5: =SUBTOTAL(3,Table13911[Running]) -> 5 | K5: Series | L5: ='RMA Main BOM'!L5 -> V2-S 4+0 Golf | AB5: 32.1892 | AG5: Currency : USD)
A6: Running | B6: Item | C6: Status | D6: Category | E6: Station | F6: Level | G6: Part Type | H6: UOM | I6: Customer P/N | J6: RMA P/N | K6: RMA Part Description | L6: Usage Qty | M6: Company | N6: Supplier | O6: Supplier Name | P6: Curren | Q6: Purchase Price | R6: Note | S6: Comment | U6: Category | V6: Trim | W6: Code | X6: Location | Z6: Pure material/unit w/o Uplift | AA6: Currency | AB6: FX Conversion | AC6: Material cost (USD) | AD6: Material usage | AE6: Total material x usage (USD) | AG6: Uplift/unit | AH6: Material usage | AI6: Total Uplift
A7: 1 | B7: 1 | D7: Chassis | F7: 1 | G7: Make | H7: each | I7: F0102089001 | J7: =IF(LEFT(I7,2)="CO",I7,IF(LEFT(I7,2)="54","HT"&I7,IF(LEFT(I7,2)="KI","KT_"&MID(I7,5,24),IF(P7="THB","GT"&I7,IF(P7="USD","GU"&I7,IF(P7="CNY","GC"&I7)))))) -> GTF0102089001 | K7: Chassis Assy / DBL A-Arm Golf / V2-4S | L7: 1 | M7: GAT | N7: P0000 | O7: Main Parts Supplier Template | P7: THB | U7: =TRIM(D7) -> Chassis | V7: =IF(U7="Seat-Option",LEFT(I7,18),TRIM(I7)) -> F0102089001 | W7: GT | X7: Local parts | AA7: =IF(W7="GU","USD","THB") -> THB | AB7: =IF(AA7="THB",AB$5,1) -> 32.1892 | AC7: =Z7/AB7 -> 0 | AD7: =L7 -> 1 | AE7: =AC7*AD7 -> 0 | AH7: =AD7 -> 1 | AI7: =AG7*AH7 -> 0
A8: 2 | B8: 1.1 | D8: Chassis | F8: 2 | G8: Buy | H8: each | I8: P-F0102089001 | J8: =IF(LEFT(I8,2)="CO",I8,IF(LEFT(I8,2)="54","HT"&I8,IF(LEFT(I8,2)="KI","KT_"&MID(I8,5,24),IF(P8="THB","GT"&I8,IF(P8="USD","GU"&I8,IF(P8="CNY","GC"&I8)))))) -> GTP-F0102089001 | K8: EDP&Powder Chassis Assy / V2-4S Golf | L8: 1 | M8: GAT | N8: X0002 | O8: Xcellent Manufacturing (Thailand) Co.,Ltd. | P8: THB | U8: =TRIM(D8) -> Chassis | V8: =IF(U8="Seat-Option",LEFT(I8,18),TRIM(I8)) -> P-F0102089001 | W8: GT | X8: Local parts | AA8: =IF(W8="GU","USD","THB") -> THB | AB8: =IF(AA8="THB",AB$5,1) -> 32.1892 | AC8: =Z8/AB8 -> 0 | AD8: =L8 -> 1 | AE8: =AC8*AD8 -> 0 | AH8: =AD8 -> 1 | AI8: =AG8*AH8 -> 0
A9: 3 | B9: 1.2 | D9: Chassis | F9: 2 | G9: Buy | H9: each | I9: Y0410024021417 | J9: =IF(LEFT(I9,2)="CO",I9,IF(LEFT(I9,2)="54","HT"&I9,IF(LEFT(I9,2)="KI","KT_"&MID(I9,5,24),IF(P9="THB","GT"&I9,IF(P9="USD","GU"&I9,IF(P9="CNY","GC"&I9)))))) -> GUY0410024021417 | K9: Instr Panel Upper Curved Beam | L9: 1 | M9: GAT | N9: Y0009 | O9: Yangzhou Wev International Trade Co.,Ltd. | P9: USD | U9: =TRIM(D9) -> Chassis | V9: =IF(U9="Seat-Option",LEFT(I9,18),TRIM(I9)) -> Y0410024021417 | W9: GU | X9: Oversea-WEV | AA9: =IF(W9="GU","USD","THB") -> USD | AB9: =IF(AA9="THB",AB$5,1) -> 1 | AC9: =Z9/AB9 -> 0 | AD9: =L9 -> 1 | AE9: =AC9*AD9 -> 0 | AH9: =AD9 -> 1 | AI9: =AG9*AH9 -> 0
A10: 4 | B10: 1.3 | D10: Chassis | F10: 2 | G10: Buy | H10: each | I10: Y0410024021418 | J10: =IF(LEFT(I10,2)="CO",I10,IF(LEFT(I10,2)="54","HT"&I10,IF(LEFT(I10,2)="KI","KT_"&MID(I10,5,24),IF(P10="THB","GT"&I10,IF(P10="USD","GU"&I10,IF(P10="CNY","GC"&I10)))))) -> GUY0410024021418 | K10: Instr Panel Upper Long Beam | L10: 2 | M10: GAT | N10: Y0009 | O10: Yangzhou Wev International Trade Co.,Ltd. | P10: USD | U10: =TRIM(D10) -> Chassis | V10: =IF(U10="Seat-Option",LEFT(I10,18),TRIM(I10)) -> Y0410024021418 | W10: GU | X10: Oversea-WEV | AA10: =IF(W10="GU","USD","THB") -> USD | AB10: =IF(AA10="THB",AB$5,1) -> 1 | AC10: =Z10/AB10 -> 0 | AD10: =L10 -> 2 | AE10: =AC10*AD10 -> 0 | AH10: =AD10 -> 2 | AI10: =AG10*AH10 -> 0
A11: 5 | B11: 1.4 | D11: Chassis | F11: 2 | G11: Buy | H11: each | I11: Y0410024021410 | J11: =IF(LEFT(I11,2)="CO",I11,IF(LEFT(I11,2)="54","HT"&I11,IF(LEFT(I11,2)="KI","KT_"&MID(I11,5,24),IF(P11="THB","GT"&I11,IF(P11="USD","GU"&I11,IF(P11="CNY","GC"&I11)))))) -> GUY0410024021410 | K11: Brake Master Cyl Mt Bracket | L11: 1 | M11: GAT | N11: Y0009 | O11: Yangzhou Wev International Trade Co.,Ltd. | P11: USD | U11: =TRIM(D11) -> Chassis | V11: =IF(U11="Seat-Option",LEFT(I11,18),TRIM(I11)) -> Y0410024021410 | W11: GU | X11: Oversea-WEV | AA11: =IF(W11="GU","USD","THB") -> USD | AB11: =IF(AA11="THB",AB$5,1) -> 1 | AC11: =Z11/AB11 -> 0 | AD11: =L11 -> 1 | AE11: =AC11*AD11 -> 0 | AH11: =AD11 -> 1 | AI11: =AG11*AH11 -> 0

Sheet Seat RMA
K2: RMA BOM No | L2: ='RMA Main BOM'!L2 -> RMA-BOM_25_180_R04 | M2: ='RMA Main BOM'!M2 -> ver. 20260302 for Order#31
K3: Customer BOM No | L3: ='RMA Main BOM'!L3 -> F0101023203 | M3: ='RMA Main BOM'!M3 -> ver. JS-S4FL-V2-202510000 for Order#31
K4: Model | L4: ='RMA Main BOM'!L4 -> V2-4SK | Z4: RMA BOM & COST | AG4: RMA Uplift COST (LCB port to RMA plant)
A5: =SUBTOTAL(3,Table1391112[Running]) -> 4 | K5: Series | L5: ='RMA Main BOM'!L5 -> V2-S 4+0 Golf | AB5: 32.1892 | AG5: Currency : USD)
A6: Running | B6: Item | C6: Status | D6: Category | E6: Station | F6: Level | G6: Part Type | H6: UOM | I6: Customer P/N | J6: RMA P/N | K6: RMA Part Description | L6: Usage Qty | M6: Company | N6: Supplier | O6: Supplier Name | P6: Curren | Q6: Purchase Price | R6: Note | S6: Comment | U6: Category | V6: Trim | W6: Code | X6: Location | Z6: Pure material/unit w/o Uplift | AA6: Currency | AB6: FX Conversion | AC6: Material cost (USD) | AD6: Material usage | AE6: Total material x usage (USD) | AG6: Uplift/unit | AH6: Material usage | AI6: Total Uplift
A7: 1 | B7: 1 | D7: Seat-Option | F7: 1 | G7: Non Buy | H7: Set | I7: KIT_SEAT_V2S_BK01BK | J7: =IF(LEFT(I7,2)="CO",I7,IF(LEFT(I7,2)="54","HT"&I7,IF(LEFT(I7,2)="KI","KT_"&MID(I7,5,24),IF(P7="THB","GT"&I7,IF(P7="USD","GU"&I7,IF(P7="CNY","GC"&I7)))))) -> KT_SEAT_V2S_BK01BK | K7: KIT_SEAT_V2S_BK01BK _BLK | L7: 1 | M7: RMA | N7: P0001 | O7: Main Parts Supplier Template | P7: THB | U7: =TRIM(D7) -> Seat-Option | V7: =IF(U7="Seat-Option",LEFT(I7,18),TRIM(I7)) -> KIT_SEAT_V2S_BK01B | W7: GT | X7: Local parts | Z7: =_xlfn.XLOOKUP((W7&V7),[1]GRN_20260331!$H:$H,[1]GRN_20260331!$W:$W,0) -> 0 | AA7: =IF(W7="GU","USD","THB") -> THB | AB7: =IF(AA7="THB",AB$5,1) -> 32.1892 | AC7: =Z7/AB7 -> 0 | AD7: =L7 -> 1 | AE7: =AC7*AD7 -> 0 | AG7: =_xlfn.XLOOKUP((W7&V7),[1]GRN_20260331!$H:$H,[1]GRN_20260331!$X:$X,0) -> 0 | AH7: =AD7 -> 1 | AI7: =AG7*AH7 -> 0
A8: 2 | B8: 1.1 | D8: Seat-Option | F8: 2 | G8: Buy | H8: Set | I8: F0103014347BK01BK033.1 | J8: =IF(LEFT(I8,2)="CO",I8,IF(LEFT(I8,2)="54","HT"&I8,IF(LEFT(I8,2)="KI","KT_"&MID(I8,5,24),IF(P8="THB","GT"&I8,IF(P8="USD","GU"&I8,IF(P8="CNY","GC"&I8)))))) -> GTF0103014347BK01BK033.1 | K8: Backrest Row1[BLK COVER BLK LINING] | L8: 1 | M8: RMA | N8: M0154 | O8: MT Cut & Sew Co.,Ltd. | P8: THB | U8: =TRIM(D8) -> Seat-Option | V8: F0103014347BK01BK0.1 | W8: GT | X8: Local parts | Z8: =_xlfn.XLOOKUP((W8&V8),[1]GRN_20260331!$H:$H,[1]GRN_20260331!$W:$W,0) -> 2802.66 | AA8: =IF(W8="GU","USD","THB") -> THB | AB8: =IF(AA8="THB",AB$5,1) -> 32.1892 | AC8: =Z8/AB8 -> 87.068333 | AD8: =L8 -> 1 | AE8: =AC8*AD8 -> 87.068333 | AG8: =_xlfn.XLOOKUP((W8&V8),[1]GRN_20260331!$H:$H,[1]GRN_20260331!$X:$X,0) -> 0 | AH8: =AD8 -> 1 | AI8: =AG8*AH8 -> 0
A9: 3 | B9: 1.2 | D9: Seat-Option | F9: 2 | G9: Buy | H9: Set | I9: F0103014347BK01BK033.2 | J9: =IF(LEFT(I9,2)="CO",I9,IF(LEFT(I9,2)="54","HT"&I9,IF(LEFT(I9,2)="KI","KT_"&MID(I9,5,24),IF(P9="THB","GT"&I9,IF(P9="USD","GU"&I9,IF(P9="CNY","GC"&I9)))))) -> GTF0103014347BK01BK033.2 | K9: Backrest Row2[BLK COVER BLK LINING] | L9: 1 | M9: RMA | N9: M0154 | O9: MT Cut & Sew Co.,Ltd. | P9: THB | U9: =TRIM(D9) -> Seat-Option | V9: F0103014347BK01BK0.2 | W9: GT | X9: Local parts | Z9: =_xlfn.XLOOKUP((W9&V9),[1]GRN_20260331!$H:$H,[1]GRN_20260331!$W:$W,0) -> 2682.66 | AA9: =IF(W9="GU","USD","THB") -> THB | AB9: =IF(AA9="THB",AB$5,1) -> 32.1892 | AC9: =Z9/AB9 -> 83.340375 | AD9: =L9 -> 1 | AE9: =AC9*AD9 -> 83.340375 | AG9: =_xlfn.XLOOKUP((W9&V9),[1]GRN_20260331!$H:$H,[1]GRN_20260331!$X:$X,0) -> 0 | AH9: =AD9 -> 1 | AI9: =AG9*AH9 -> 0
A10: 4 | B10: 1.3 | D10: Seat-Option | F10: 2 | G10: Buy | H10: Set | I10: F0103014348BK01BK0300 | J10: =IF(LEFT(I10,2)="CO",I10,IF(LEFT(I10,2)="54","HT"&I10,IF(LEFT(I10,2)="KI","KT_"&MID(I10,5,24),IF(P10="THB","GT"&I10,IF(P10="USD","GU"&I10,IF(P10="CNY","GC"&I10)))))) -> GTF0103014348BK01BK0300 | K10: Cushion Row1[BLK COVER BLK LINING] | L10: 1 | M10: RMA | N10: M0154 | O10: MT Cut & Sew Co.,Ltd. | P10: THB | U10: =TRIM(D10) -> Seat-Option | V10: =IF(U10="Seat-Option",LEFT(I10,18),TRIM(I10)) -> F0103014348BK01BK0 | W10: GT | X10: Local parts | Z10: =_xlfn.XLOOKUP((W10&V10),[1]GRN_20260331!$H:$H,[1]GRN_20260331!$W:$W,0) -> 1412.3 | AA10: =IF(W10="GU","USD","THB") -> THB | AB10: =IF(AA10="THB",AB$5,1) -> 32.1892 | AC10: =Z10/AB10 -> 43.874964 | AD10: =L10 -> 1 | AE10: =AC10*AD10 -> 43.874964 | AG10: =_xlfn.XLOOKUP((W10&V10),[1]GRN_20260331!$H:$H,[1]GRN_20260331!$X:$X,0) -> 0 | AH10: =AD10 -> 1 | AI10: =AG10*AH10 -> 0
A11: 5 | B11: 1.4 | D11: Seat-Option | F11: 2 | G11: Buy | H11: Set | I11: F0103014349BK01BK0300 | J11: =IF(LEFT(I11,2)="CO",I11,IF(LEFT(I11,2)="54","HT"&I11,IF(LEFT(I11,2)="KI","KT_"&MID(I11,5,24),IF(P11="THB","GT"&I11,IF(P11="USD","GU"&I11,IF(P11="CNY","GC"&I11)))))) -> GTF0103014349BK01BK0300 | K11: Cushion Row2[BLK COVER BLK LINING] | L11: 1 | M11: RMA | N11: M0154 | O11: MT Cut & Sew Co.,Ltd. | P11: THB | U11: =TRIM(D11) -> Seat-Option | V11: =IF(U11="Seat-Option",LEFT(I11,18),TRIM(I11)) -> F0103014349BK01BK0 | W11: GT | X11: Local parts | Z11: =_xlfn.XLOOKUP((W11&V11),[1]GRN_20260331!$H:$H,[1]GRN_20260331!$W:$W,0) -> 1412.3 | AA11: =IF(W11="GU","USD","THB") -> THB | AB11: =IF(AA11="THB",AB$5,1) -> 32.1892 | AC11: =Z11/AB11 -> 43.874964 | AD11: =L11 -> 1 | AE11: =AC11*AD11 -> 43.874964 | AG11: =_xlfn.XLOOKUP((W11&V11),[1]GRN_20260331!$H:$H,[1]GRN_20260331!$X:$X,0) -> 0 | AH11: =AD11 -> 1 | AI11: =AG11*AH11 -> 0

Sheet Paint RMA
K2: RMA BOM No | L2: ='RMA Main BOM'!L2 -> RMA-BOM_25_180_R04 | M2: ='RMA Main BOM'!M2 -> ver. 20260302 for Order#31
K3: Customer BOM No | L3: ='RMA Main BOM'!L3 -> F0101023203 | M3: ='RMA Main BOM'!M3 -> ver. JS-S4FL-V2-202510000 for Order#31
K4: Model | L4: ='RMA Main BOM'!L4 -> V2-4SK | Z4: RMA BOM & COST | AG4: RMA Uplift COST (LCB port to RMA plant)
A5: =SUBTOTAL(3,Table139111213[Running]) -> 8 | K5: Series | L5: ='RMA Main BOM'!L5 -> V2-S 4+0 Golf | AB5: 32.1892 | AG5: Currency : USD)
A6: Running | B6: Item | C6: Status | D6: Category | E6: Station | F6: Level | G6: Part Type | H6: UOM | I6: Customer P/N | J6: RMA P/N | K6: RMA Part Description | L6: Usage Qty | M6: Company | N6: Supplier | O6: Supplier Name | P6: Curren | Q6: Purchase Price | R6: Note | S6: Comment | U6: Category | V6: Trim | W6: Code | X6: Location | Z6: Pure material/unit w/o Uplift | AA6: Currency | AB6: FX Conversion | AC6: Material cost (USD) | AD6: Material usage | AE6: Total material x usage (USD) | AG6: Uplift/unit | AH6: Material usage | AI6: Total Uplift
A7: 1 | B7: 1 | D7: Plastic Paint-Option | F7: 1 | G7: Non Buy | H7: Set | I7: KIT_PNT_V2S_SMG440MZ | J7: =IF(LEFT(I7,2)="CO",I7,IF(LEFT(I7,2)="54","HT"&I7,IF(LEFT(I7,2)="KI","KT_"&MID(I7,5,24),IF(P7="THB","GT"&I7,IF(P7="USD","GU"&I7,IF(P7="CNY","GC"&I7)))))) -> KT_PNT_V2S_SMG440MZ | K7: BODY PLASTIC W/PAINT[RED] | L7: 1 | M7: RMA | N7: P0001 | O7: Main Parts Supplier Template | P7: THB | U7: =TRIM(D7) -> Plastic Paint-Option | V7: =IF(U7="Seat-Option",LEFT(I7,18),TRIM(I7)) -> KIT_PNT_V2S_SMG440MZ | W7: GT | X7: Local parts | Z7: =_xlfn.XLOOKUP((W7&V7),[1]GRN_20260331!$H:$H,[1]GRN_20260331!$W:$W,0) -> 0 | AA7: =IF(W7="GU","USD","THB") -> THB | AB7: =IF(AA7="THB",AB$5,1) -> 32.1892 | AC7: =Z7/AB7 -> 0 | AD7: =L7 -> 1 | AE7: =AC7*AD7 -> 0 | AG7: =_xlfn.XLOOKUP((W7&V7),[1]GRN_20260331!$H:$H,[1]GRN_20260331!$X:$X,0) -> 0 | AH7: =AD7 -> 1 | AI7: =AG7*AH7 -> 0
A8: 2 | B8: 1.01 | D8: Plastic Paint-Option | F8: 2 | G8: Make | H8: Each | I8: F0102089003PSMG440MZ | J8: =IF(LEFT(I8,2)="CO",I8,IF(LEFT(I8,2)="54","HT"&I8,IF(LEFT(I8,2)="KI","KT_"&MID(I8,5,24),IF(P8="THB","GT"&I8,IF(P8="USD","GU"&I8,IF(P8="CNY","GC"&I8)))))) -> GTF0102089003PSMG440MZ | K8: FRT COVER PAINT[RED] | L8: 1 | M8: RMA | N8: P0001 | O8: Main Parts Supplier Template | P8: THB | U8: =TRIM(D8) -> Plastic Paint-Option | V8: =IF(U8="Seat-Option",LEFT(I8,18),TRIM(I8)) -> F0102089003PSMG440MZ | W8: GT | X8: Local parts | Z8: =_xlfn.XLOOKUP((W8&V8),[1]GRN_20260331!$H:$H,[1]GRN_20260331!$W:$W,0) -> 0 | AA8: =IF(W8="GU","USD","THB") -> THB | AB8: =IF(AA8="THB",AB$5,1) -> 32.1892 | AC8: =Z8/AB8 -> 0 | AD8: =L8 -> 1 | AE8: =AC8*AD8 -> 0 | AG8: =_xlfn.XLOOKUP((W8&V8),[1]GRN_20260331!$H:$H,[1]GRN_20260331!$X:$X,0) -> 0 | AH8: =AD8 -> 1 | AI8: =AG8*AH8 -> 0
A9: 3 | B9: 1.02 | D9: Plastic Paint-Option | F9: 3 | G9: Buy | H9: Each | I9: P-F0102089003SMG440MZ | J9: =IF(LEFT(I9,2)="CO",I9,IF(LEFT(I9,2)="54","HT"&I9,IF(LEFT(I9,2)="KI","KT_"&MID(I9,5,24),IF(P9="THB","GT"&I9,IF(P9="USD","GU"&I9,IF(P9="CNY","GC"&I9)))))) -> GTP-F0102089003SMG440MZ | K9: PAINT PROCESS FRT COVER[RED- SMG440M] | L9: 1 | M9: RMA | N9: P0001 | O9: Main Parts Supplier Template | P9: THB | R9: Non-specific supplier | U9: =TRIM(D9) -> Plastic Paint-Option | V9: =IF(U9="Seat-Option",LEFT(I9,18),TRIM(I9)) -> P-F0102089003SMG440MZ | W9: GT | X9: Local parts | Z9: =_xlfn.XLOOKUP((W9&V9),[1]GRN_20260331!$H:$H,[1]GRN_20260331!$W:$W,0) -> 0 | AA9: =IF(W9="GU","USD","THB") -> THB | AB9: =IF(AA9="THB",AB$5,1) -> 32.1892 | AC9: =Z9/AB9 -> 0 | AD9: =L9 -> 1 | AE9: =AC9*AD9 -> 0 | AG9: =_xlfn.XLOOKUP((W9&V9),[1]GRN_20260331!$H:$H,[1]GRN_20260331!$X:$X,0) -> 0 | AH9: =AD9 -> 1 | AI9: =AG9*AH9 -> 0
A10: 4 | B10: 1.03 | D10: Plastic | F10: 3 | G10: Buy | H10: Each | I10: F0102089003 | J10: =IF(LEFT(I10,2)="CO",I10,IF(LEFT(I10,2)="54","HT"&I10,IF(LEFT(I10,2)="KI","KT_"&MID(I10,5,24),IF(P10="THB","GT"&I10,IF(P10="USD","GU"&I10,IF(P10="CNY","GC"&I10)))))) -> GTF0102089003 | K10: FRT COVER | L10: 1 | M10: RMA | N10: P0238 | O10: 687 Plastic and Mold Co.,Ltd. | P10: THB | U10: =TRIM(D10) -> Plastic | V10: =IF(U10="Seat-Option",LEFT(I10,18),TRIM(I10)) -> F0102089003 | W10: GT | X10: Local parts | Z10: =_xlfn.XLOOKUP((W10&V10),[1]GRN_20260331!$H:$H,[1]GRN_20260331!$W:$W,0) -> 473.51 | AA10: =IF(W10="GU","USD","THB") -> THB | AB10: =IF(AA10="THB",AB$5,1) -> 32.1892 | AC10: =Z10/AB10 -> 14.710213 | AD10: =L10 -> 1 | AE10: =AC10*AD10 -> 14.710213 | AG10: =_xlfn.XLOOKUP((W10&V10),[1]GRN_20260331!$H:$H,[1]GRN_20260331!$X:$X,0) -> 0 | AH10: =AD10 -> 1 | AI10: =AG10*AH10 -> 0
A11: 5 | B11: 1.04 | D11: Plastic Paint-Option | F11: 2 | G11: Make | H11: Each | I11: F0102089006PSMG440MZ | J11: =IF(LEFT(I11,2)="CO",I11,IF(LEFT(I11,2)="54","HT"&I11,IF(LEFT(I11,2)="KI","KT_"&MID(I11,5,24),IF(P11="THB","GT"&I11,IF(P11="USD","GU"&I11,IF(P11="CNY","GC"&I11)))))) -> GTF0102089006PSMG440MZ | K11: FRT STORAGE COVER PAINT[RED] | L11: 1 | M11: RMA | N11: P0001 | O11: Main Parts Supplier Template | P11: THB | U11: =TRIM(D11) -> Plastic Paint-Option | V11: =IF(U11="Seat-Option",LEFT(I11,18),TRIM(I11)) -> F0102089006PSMG440MZ | W11: GT | X11: Local parts | Z11: =_xlfn.XLOOKUP((W11&V11),[1]GRN_20260331!$H:$H,[1]GRN_20260331!$W:$W,0) -> 0 | AA11: =IF(W11="GU","USD","THB") -> THB | AB11: =IF(AA11="THB",AB$5,1) -> 32.1892 | AC11: =Z11/AB11 -> 0 | AD11: =L11 -> 1 | AE11: =AC11*AD11 -> 0 | AG11: =_xlfn.XLOOKUP((W11&V11),[1]GRN_20260331!$H:$H,[1]GRN_20260331!$X:$X,0) -> 0 | AH11: =AD11 -> 1 | AI11: =AG11*AH11 -> 0
A12: 6 | B12: 1.05 | D12: Plastic Paint-Option | F12: 3 | G12: Buy | H12: Each | I12: P-F0102089006SMG440MZ | J12: =IF(LEFT(I12,2)="CO",I12,IF(LEFT(I12,2)="54","HT"&I12,IF(LEFT(I12,2)="KI","KT_"&MID(I12,5,24),IF(P12="THB","GT"&I12,IF(P12="USD","GU"&I12,IF(P12="CNY","GC"&I12)))))) -> GTP-F0102089006SMG440MZ | K12: PAINT FRT STORAGE COVER[RED- SMG440M] | L12: 1 | M12: RMA | N12: P0001 | O12: Main Parts Supplier Template | P12: THB | R12: Non-specific supplier | U12: =TRIM(D12) -> Plastic Paint-Option | V12: =IF(U12="Seat-Option",LEFT(I12,18),TRIM(I12)) -> P-F0102089006SMG440MZ | W12: GT | X12: Local parts | Z12: =_xlfn.XLOOKUP((W12&V12),[1]GRN_20260331!$H:$H,[1]GRN_20260331!$W:$W,0) -> 0 | AA12: =IF(W12="GU","USD","THB") -> THB | AB12: =IF(AA12="THB",AB$5,1) -> 32.1892 | AC12: =Z12/AB12 -> 0 | AD12: =L12 -> 1 | AE12: =AC12*AD12 -> 0 | AG12: =_xlfn.XLOOKUP((W12&V12),[1]GRN_20260331!$H:$H,[1]GRN_20260331!$X:$X,0) -> 0 | AH12: =AD12 -> 1 | AI12: =AG12*AH12 -> 0
A13: 7 | B13: 1.06 | D13: Plastic | F13: 3 | G13: Buy | H13: Each | I13: F0102089006 | J13: =IF(LEFT(I13,2)="CO",I13,IF(LEFT(I13,2)="54","HT"&I13,IF(LEFT(I13,2)="KI","KT_"&MID(I13,5,24),IF(P13="THB","GT"&I13,IF(P13="USD","GU"&I13,IF(P13="CNY","GC"&I13)))))) -> GTF0102089006 | K13: FRT STORAGE COMPARTMENT COVER | L13: 1 | M13: RMA | N13: T0255 | O13: Tayih Kenmos Autoparts Co.,Ltd. | P13: THB | U13: =TRIM(D13) -> Plastic | V13: =IF(U13="Seat-Option",LEFT(I13,18),TRIM(I13)) -> F0102089006 | W13: GT | X13: Local parts | Z13: =_xlfn.XLOOKUP((W13&V13),[1]GRN_20260331!$H:$H,[1]GRN_20260331!$W:$W,0) -> 932.37 | AA13: =IF(W13="GU","USD","THB") -> THB | AB13: =IF(AA13="THB",AB$5,1) -> 32.1892 | AC13: =Z13/AB13 -> 28.965305 | AD13: =L13 -> 1 | AE13: =AC13*AD13 -> 28.965305 | AG13: =_xlfn.XLOOKUP((W13&V13),[1]GRN_20260331!$H:$H,[1]GRN_20260331!$X:$X,0) -> 0 | AH13: =AD13 -> 1 | AI13: =AG13*AH13 -> 0
A14: 8 | B14: 1.07 | D14: Plastic Paint-Option | F14: 2 | G14: Make | H14: Each | I14: F0102089013PSMG440MZ | J14: =IF(LEFT(I14,2)="CO",I14,IF(LEFT(I14,2)="54","HT"&I14,IF(LEFT(I14,2)="KI","KT_"&MID(I14,5,24),IF(P14="THB","GT"&I14,IF(P14="USD","GU"&I14,IF(P14="CNY","GC"&I14)))))) -> GTF0102089013PSMG440MZ | K14: FRT BUMPER DECO PART 1 PAINT[RED] | L14: 1 | M14: RMA | N14: P0001 | O14: Main Parts Supplier Template | P14: THB | U14: =TRIM(D14) -> Plastic Paint-Option | V14: =IF(U14="Seat-Option",LEFT(I14,18),TRIM(I14)) -> F0102089013PSMG440MZ | W14: GT | X14: Local parts | Z14: =_xlfn.XLOOKUP((W14&V14),[1]GRN_20260331!$H:$H,[1]GRN_20260331!$W:$W,0) -> 0 | AA14: =IF(W14="GU","USD","THB") -> THB | AB14: =IF(AA14="THB",AB$5,1) -> 32.1892 | AC14: =Z14/AB14 -> 0 | AD14: =L14 -> 1 | AE14: =AC14*AD14 -> 0 | AG14: =_xlfn.XLOOKUP((W14&V14),[1]GRN_20260331!$H:$H,[1]GRN_20260331!$X:$X,0) -> 0 | AH14: =AD14 -> 1 | AI14: =AG14*AH14 -> 0
A15: 9 | B15: 1.08 | D15: Plastic Paint-Option | F15: 3 | G15: Buy | H15: Each | I15: P-F0102089013SMG440MZ | J15: =IF(LEFT(I15,2)="CO",I15,IF(LEFT(I15,2)="54","HT"&I15,IF(LEFT(I15,2)="KI","KT_"&MID(I15,5,24),IF(P15="THB","GT"&I15,IF(P15="USD","GU"&I15,IF(P15="CNY","GC"&I15)))))) -> GTP-F0102089013SMG440MZ | K15: PAINT FRT BUMPER DECO 1[RED- SMG440M] | L15: 1 | M15: RMA | N15: P0001 | O15: Main Parts Supplier Template | P15: THB | R15: Non-specific supplier | U15: =TRIM(D15) -> Plastic Paint-Option | V15: =IF(U15="Seat-Option",LEFT(I15,18),TRIM(I15)) -> P-F0102089013SMG440MZ | W15: GT | X15: Local parts | Z15: =_xlfn.XLOOKUP((W15&V15),[1]GRN_20260331!$H:$H,[1]GRN_20260331!$W:$W,0) -> 0 | AA15: =IF(W15="GU","USD","THB") -> THB | AB15: =IF(AA15="THB",AB$5,1) -> 32.1892 | AC15: =Z15/AB15 -> 0 | AD15: =L15 -> 1 | AE15: =AC15*AD15 -> 0 | AG15: =_xlfn.XLOOKUP((W15&V15),[1]GRN_20260331!$H:$H,[1]GRN_20260331!$X:$X,0) -> 0 | AH15: =AD15 -> 1 | AI15: =AG15*AH15 -> 0
A16: 10 | B16: 1.09 | D16: Plastic | F16: 3 | G16: Buy | H16: Each | I16: F0102089013 | J16: =IF(LEFT(I16,2)="CO",I16,IF(LEFT(I16,2)="54","HT"&I16,IF(LEFT(I16,2)="KI","KT_"&MID(I16,5,24),IF(P16="THB","GT"&I16,IF(P16="USD","GU"&I16,IF(P16="CNY","GC"&I16)))))) -> GTF0102089013 | K16: FRT BUMPER DECO PART 1 | L16: 1 | M16: RMA | N16: S0403 | O16: Sombat Plastic Co.,Ltd. | P16: THB | U16: =TRIM(D16) -> Plastic | V16: =IF(U16="Seat-Option",LEFT(I16,18),TRIM(I16)) -> F0102089013 | W16: GT | X16: Local parts | Z16: =_xlfn.XLOOKUP((W16&V16),[1]GRN_20260331!$H:$H,[1]GRN_20260331!$W:$W,0) -> 70.96 | AA16: =IF(W16="GU","USD","THB") -> THB | AB16: =IF(AA16="THB",AB$5,1) -> 32.1892 | AC16: =Z16/AB16 -> 2.2044661 | AD16: =L16 -> 1 | AE16: =AC16*AD16 -> 2.2044661 | AG16: =_xlfn.XLOOKUP((W16&V16),[1]GRN_20260331!$H:$H,[1]GRN_20260331!$X:$X,0) -> 0 | AH16: =AD16 -> 1 | AI16: =AG16*AH16 -> 0
A17: 11 | B17: 1.1 | D17: Plastic Paint-Option | F17: 2 | G17: Make | H17: Each | I17: F0102089037PSMG440MZ | J17: =IF(LEFT(I17,2)="CO",I17,IF(LEFT(I17,2)="54","HT"&I17,IF(LEFT(I17,2)="KI","KT_"&MID(I17,5,24),IF(P17="THB","GT"&I17,IF(P17="USD","GU"&I17,IF(P17="CNY","GC"&I17)))))) -> GTF0102089037PSMG440MZ | K17: INSTR PANEL DECO STRIP L PAINT[RED] | L17: 1 | M17: RMA | N17: P0001 | O17: Main Parts Supplier Template | P17: THB | U17: =TRIM(D17) -> Plastic Paint-Option | V17: =IF(U17="Seat-Option",LEFT(I17,18),TRIM(I17)) -> F0102089037PSMG440MZ | W17: GT | X17: Local parts | Z17: =_xlfn.XLOOKUP((W17&V17),[1]GRN_20260331!$H:$H,[1]GRN_20260331!$W:$W,0) -> 0 | AA17: =IF(W17="GU","USD","THB") -> THB | AB17: =IF(AA17="THB",AB$5,1) -> 32.1892 | AC17: =Z17/AB17 -> 0 | AD17: =L17 -> 1 | AE17: =AC17*AD17 -> 0 | AG17: =_xlfn.XLOOKUP((W17&V17),[1]GRN_20260331!$H:$H,[1]GRN_20260331!$X:$X,0) -> 0 | AH17: =AD17 -> 1 | AI17: =AG17*AH17 -> 0
A18: 12 | B18: 1.11 | D18: Plastic Paint-Option | F18: 3 | G18: Buy | H18: Each | I18: P-F0102089037SMG440MZ | J18: =IF(LEFT(I18,2)="CO",I18,IF(LEFT(I18,2)="54","HT"&I18,IF(LEFT(I18,2)="KI","KT_"&MID(I18,5,24),IF(P18="THB","GT"&I18,IF(P18="USD","GU"&I18,IF(P18="CNY","GC"&I18)))))) -> GTP-F0102089037SMG440MZ | K18: PAINT IP DECO STRIP L[RED- SMG440M] | L18: 1 | M18: RMA | N18: P0001 | O18: Main Parts Supplier Template | P18: THB | R18: Non-specific supplier | U18: =TRIM(D18) -> Plastic Paint-Option | V18: =IF(U18="Seat-Option",LEFT(I18,18),TRIM(I18)) -> P-F0102089037SMG440MZ | W18: GT | X18: Local parts | Z18: =_xlfn.XLOOKUP((W18&V18),[1]GRN_20260331!$H:$H,[1]GRN_20260331!$W:$W,0) -> 0 | AA18: =IF(W18="GU","USD","THB") -> THB | AB18: =IF(AA18="THB",AB$5,1) -> 32.1892 | AC18: =Z18/AB18 -> 0 | AD18: =L18 -> 1 | AE18: =AC18*AD18 -> 0 | AG18: =_xlfn.XLOOKUP((W18&V18),[1]GRN_20260331!$H:$H,[1]GRN_20260331!$X:$X,0) -> 0 | AH18: =AD18 -> 1 | AI18: =AG18*AH18 -> 0
A19: 13 | B19: 1.12 | D19: Plastic | F19: 3 | G19: Buy | H19: Each | I19: F0102089037 | J19: =IF(LEFT(I19,2)="CO",I19,IF(LEFT(I19,2)="54","HT"&I19,IF(LEFT(I19,2)="KI","KT_"&MID(I19,5,24),IF(P19="THB","GT"&I19,IF(P19="USD","GU"&I19,IF(P19="CNY","GC"&I19)))))) -> GTF0102089037 | K19: INSTR PANEL DECO STRIP L | L19: 1 | M19: RMA | N19: J0019 | O19: J.V. (Thailand) Co.,Ltd. | P19: THB | U19: =TRIM(D19) -> Plastic | V19: =IF(U19="Seat-Option",LEFT(I19,18),TRIM(I19)) -> F0102089037 | W19: GT | X19: Local parts | Z19: =_xlfn.XLOOKUP((W19&V19),[1]GRN_20260331!$H:$H,[1]GRN_20260331!$W:$W,0) -> 10 | AA19: =IF(W19="GU","USD","THB") -> THB | AB19: =IF(AA19="THB",AB$5,1) -> 32.1892 | AC19: =Z19/AB19 -> 0.3106632 | AD19: =L19 -> 1 | AE19: =AC19*AD19 -> 0.3106632 | AG19: =_xlfn.XLOOKUP((W19&V19),[1]GRN_20260331!$H:$H,[1]GRN_20260331!$X:$X,0) -> 0 | AH19: =AD19 -> 1 | AI19: =AG19*AH19 -> 0
A20: 14 | B20: 1.13 | D20: Plastic Paint-Option | F20: 2 | G20: Make | H20: Each | I20: F0102089038PSMG440MZ | J20: =IF(LEFT(I20,2)="CO",I20,IF(LEFT(I20,2)="54","HT"&I20,IF(LEFT(I20,2)="KI","KT_"&MID(I20,5,24),IF(P20="THB","GT"&I20,IF(P20="USD","GU"&I20,IF(P20="CNY","GC"&I20)))))) -> GTF0102089038PSMG440MZ | K20: INSTR PANEL DECO STRIP R PAINT[RED] | L20: 1 | M20: RMA | N20: P0001 | O20: Main Parts Supplier Template | P20: THB | U20: =TRIM(D20) -> Plastic Paint-Option | V20: =IF(U20="Seat-Option",LEFT(I20,18),TRIM(I20)) -> F0102089038PSMG440MZ | W20: GT | X20: Local parts | Z20: =_xlfn.XLOOKUP((W20&V20),[1]GRN_20260331!$H:$H,[1]GRN_20260331!$W:$W,0) -> 0 | AA20: =IF(W20="GU","USD","THB") -> THB | AB20: =IF(AA20="THB",AB$5,1) -> 32.1892 | AC20: =Z20/AB20 -> 0 | AD20: =L20 -> 1 | AE20: =AC20*AD20 -> 0 | AG20: =_xlfn.XLOOKUP((W20&V20),[1]GRN_20260331!$H:$H,[1]GRN_20260331!$X:$X,0) -> 0 | AH20: =AD20 -> 1 | AI20: =AG20*AH20 -> 0
A21: 15 | B21: 1.14 | D21: Plastic Paint-Option | F21: 3 | G21: Buy | H21: Each | I21: P-F0102089038SMG440MZ | J21: =IF(LEFT(I21,2)="CO",I21,IF(LEFT(I21,2)="54","HT"&I21,IF(LEFT(I21,2)="KI","KT_"&MID(I21,5,24),IF(P21="THB","GT"&I21,IF(P21="USD","GU"&I21,IF(P21="CNY","GC"&I21)))))) -> GTP-F0102089038SMG440MZ | K21: PAINT IP DECO STRIP R[RED- SMG440M] | L21: 1 | M21: RMA | N21: P0001 | O21: Main Parts Supplier Template | P21: THB | R21: Non-specific supplier | U21: =TRIM(D21) -> Plastic Paint-Option | V21: =IF(U21="Seat-Option",LEFT(I21,18),TRIM(I21)) -> P-F0102089038SMG440MZ | W21: GT | X21: Local parts | Z21: =_xlfn.XLOOKUP((W21&V21),[1]GRN_20260331!$H:$H,[1]GRN_20260331!$W:$W,0) -> 0 | AA21: =IF(W21="GU","USD","THB") -> THB | AB21: =IF(AA21="THB",AB$5,1) -> 32.1892 | AC21: =Z21/AB21 -> 0 | AD21: =L21 -> 1 | AE21: =AC21*AD21 -> 0 | AG21: =_xlfn.XLOOKUP((W21&V21),[1]GRN_20260331!$H:$H,[1]GRN_20260331!$X:$X,0) -> 0 | AH21: =AD21 -> 1 | AI21: =AG21*AH21 -> 0
A22: 16 | B22: 1.15 | D22: Plastic | F22: 3 | G22: Buy | H22: Each | I22: F0102089038 | J22: =IF(LEFT(I22,2)="CO",I22,IF(LEFT(I22,2)="54","HT"&I22,IF(LEFT(I22,2)="KI","KT_"&MID(I22,5,24),IF(P22="THB","GT"&I22,IF(P22="USD","GU"&I22,IF(P22="CNY","GC"&I22)))))) -> GTF0102089038 | K22: INSTR PANEL DECO STRIP R | L22: 1 | M22: RMA | N22: J0019 | O22: J.V. (Thailand) Co.,Ltd. | P22: THB | U22: =TRIM(D22) -> Plastic | V22: =IF(U22="Seat-Option",LEFT(I22,18),TRIM(I22)) -> F0102089038 | W22: GT | X22: Local parts | Z22: =_xlfn.XLOOKUP((W22&V22),[1]GRN_20260331!$H:$H,[1]GRN_20260331!$W:$W,0) -> 18 | AA22: =IF(W22="GU","USD","THB") -> THB | AB22: =IF(AA22="THB",AB$5,1) -> 32.1892 | AC22: =Z22/AB22 -> 0.55919377 | AD22: =L22 -> 1 | AE22: =AC22*AD22 -> 0.55919377 | AG22: =_xlfn.XLOOKUP((W22&V22),[1]GRN_20260331!$H:$H,[1]GRN_20260331!$X:$X,0) -> 0 | AH22: =AD22 -> 1 | AI22: =AG22*AH22 -> 0
